Workbook

Sheet DB CONECTOR
A1: =IFERROR(__xludf.DUMMYFUNCTION("IMPORTRANGE(""1dSSQGdzji-I-S89PZ6JN-XosTLpqBKogy6v1RSpLOIY"",""CATEGORIAS TOURS!Categoria[Categoria]"")"),"Cultura") -> Cultura | C1: =IFERROR(__xludf.DUMMYFUNCTION("IMPORTRANGE(""1dSSQGdzji-I-S89PZ6JN-XosTLpqBKogy6v1RSpLOIY"",""DIFICULTAD TOUR!Dificultad[DIFICULTAD]"")"),"Facil") -> Facil | E1: =IFERROR(__xludf.DUMMYFUNCTION("IMPORTRANGE(""1dSSQGdzji-I-S89PZ6JN-XosTLpqBKogy6v1RSpLOIY"",""PUBLICO OBJETIVO!Publico[Publico]"")"),"Familias") -> Familias | G1: =IFERROR(__xludf.DUMMYFUNCTION("IMPORTRANGE(""1dSSQGdzji-I-S89PZ6JN-XosTLpqBKogy6v1RSpLOIY"",""IDIOMAS DISPONIBLES!Idiomas[idioma]"")"),"Español") -> Español | I1: =IFERROR(__xludf.DUMMYFUNCTION("IMPORTRANGE(""1dSSQGdzji-I-S89PZ6JN-XosTLpqBKogy6v1RSpLOIY"",""TEMPORALIDAD!Temporada[Temporada]"")"),"Enero") -> Enero | K1: =IFERROR(__xludf.DUMMYFUNCTION("IMPORTRANGE(""1dSSQGdzji-I-S89PZ6JN-XosTLpqBKogy6v1RSpLOIY"",""TEMPORALIDAD!Temporada[Duracion]"")"),"4 Horas") -> 4 Horas | L1: 40 | N1: =IFERROR(__xludf.DUMMYFUNCTION("IMPORTRANGE(""1dSSQGdzji-I-S89PZ6JN-XosTLpqBKogy6v1RSpLOIY"",""PROVEEDORES TRANSPORTE!ProvedorTransporte"")"),"TRANSTOUR CIUDAD ROJA") -> TRANSTOUR CIUDAD ROJA | O1: =IFERROR(__xludf.DUMMYFUNCTION("""COMPUTED_VALUE"""),"NESTOR REINOSO GUAMAN") -> NESTOR REINOSO GUAMAN | Q1: =IFERROR(__xludf.DUMMYFUNCTION("""COMPUTED_VALUE"""),4.0) -> 4 | R1: =IFERROR(__xludf.DUMMYFUNCTION("""COMPUTED_VALUE"""),"4 HORAS") -> 4 HORAS | S1: =IFERROR(__xludf.DUMMYFUNCTION("""COMPUTED_VALUE"""),80.0) -> 80 | T1: =IFERROR(__xludf.DUMMYFUNCTION("""COMPUTED_VALUE"""),120.0) -> 120
A2: =IFERROR(__xludf.DUMMYFUNCTION("""COMPUTED_VALUE"""),"Arquitectura") -> Arquitectura | C2: =IFERROR(__xludf.DUMMYFUNCTION("""COMPUTED_VALUE"""),"Intermedio") -> Intermedio | E2: =IFERROR(__xludf.DUMMYFUNCTION("""COMPUTED_VALUE"""),"Aventureros") -> Aventureros | G2: =IFERROR(__xludf.DUMMYFUNCTION("""COMPUTED_VALUE"""),"Ingles") -> Ingles | I2: =IFERROR(__xludf.DUMMYFUNCTION("""COMPUTED_VALUE"""),"Febrero") -> Febrero | K2: =IFERROR(__xludf.DUMMYFUNCTION("""COMPUTED_VALUE"""),"8 Horas") -> 8 Horas | L2: 70 | N2: =IFERROR(__xludf.DUMMYFUNCTION("""COMPUTED_VALUE"""),"TRANSTOUR CIUDAD ROJA") -> TRANSTOUR CIUDAD ROJA | O2: =IFERROR(__xludf.DUMMYFUNCTION("""COMPUTED_VALUE"""),"NESTOR REINOSO GUAMAN") -> NESTOR REINOSO GUAMAN | Q2: =IFERROR(__xludf.DUMMYFUNCTION("""COMPUTED_VALUE"""),7.0) -> 7 | R2: =IFERROR(__xludf.DUMMYFUNCTION("""COMPUTED_VALUE"""),"4 HORAS") -> 4 HORAS | S2: =IFERROR(__xludf.DUMMYFUNCTION("""COMPUTED_VALUE"""),90.0) -> 90 | T2: =IFERROR(__xludf.DUMMYFUNCTION("""COMPUTED_VALUE"""),130.0) -> 130
A3: =IFERROR(__xludf.DUMMYFUNCTION("""COMPUTED_VALUE"""),"Gastronomía") -> Gastronomía | C3: =IFERROR(__xludf.DUMMYFUNCTION("""COMPUTED_VALUE"""),"Medio") -> Medio | E3: =IFERROR(__xludf.DUMMYFUNCTION("""COMPUTED_VALUE"""),"Culturistas") -> Culturistas | I3: =IFERROR(__xludf.DUMMYFUNCTION("""COMPUTED_VALUE"""),"Marzo") -> Marzo | K3: =IFERROR(__xludf.DUMMYFUNCTION("""COMPUTED_VALUE"""),"2 Horas") -> 2 Horas | N3: =IFERROR(__xludf.DUMMYFUNCTION("""COMPUTED_VALUE"""),"TRANSTOUR CIUDAD ROJA") -> TRANSTOUR CIUDAD ROJA | O3: =IFERROR(__xludf.DUMMYFUNCTION("""COMPUTED_VALUE"""),"NESTOR REINOSO GUAMAN") -> NESTOR REINOSO GUAMAN | Q3: =IFERROR(__xludf.DUMMYFUNCTION("""COMPUTED_VALUE"""),12.0) -> 12 | R3: =IFERROR(__xludf.DUMMYFUNCTION("""COMPUTED_VALUE"""),"4 HORAS") -> 4 HORAS | S3: =IFERROR(__xludf.DUMMYFUNCTION("""COMPUTED_VALUE"""),120.0) -> 120 | T3: =IFERROR(__xludf.DUMMYFUNCTION("""COMPUTED_VALUE"""),150.0) -> 150
A4: =IFERROR(__xludf.DUMMYFUNCTION("""COMPUTED_VALUE"""),"Naturaleza") -> Naturaleza | C4: =IFERROR(__xludf.DUMMYFUNCTION("""COMPUTED_VALUE"""),"Dificil") -> Dificil | E4: =IFERROR(__xludf.DUMMYFUNCTION("""COMPUTED_VALUE"""),"Fotografos") -> Fotografos | I4: =IFERROR(__xludf.DUMMYFUNCTION("""COMPUTED_VALUE"""),"Abril") -> Abril | N4: =IFERROR(__xludf.DUMMYFUNCTION("""COMPUTED_VALUE"""),"TRANSTOUR CIUDAD ROJA") -> TRANSTOUR CIUDAD ROJA | O4: =IFERROR(__xludf.DUMMYFUNCTION("""COMPUTED_VALUE"""),"NESTOR REINOSO GUAMAN") -> NESTOR REINOSO GUAMAN | Q4: =IFERROR(__xludf.DUMMYFUNCTION("""COMPUTED_VALUE"""),16.0) -> 16 | R4: =IFERROR(__xludf.DUMMYFUNCTION("""COMPUTED_VALUE"""),"4 HORAS") -> 4 HORAS | S4: =IFERROR(__xludf.DUMMYFUNCTION("""COMPUTED_VALUE"""),140.0) -> 140 | T4: =IFERROR(__xludf.DUMMYFUNCTION("""COMPUTED_VALUE"""),180.0) -> 180
A5: =IFERROR(__xludf.DUMMYFUNCTION("""COMPUTED_VALUE"""),"Artesanal") -> Artesanal | C5: =IFERROR(__xludf.DUMMYFUNCTION("""COMPUTED_VALUE"""),"Muy Dificil") -> Muy Dificil | E5: =IFERROR(__xludf.DUMMYFUNCTION("""COMPUTED_VALUE"""),"Extranjeros") -> Extranjeros | I5: =IFERROR(__xludf.DUMMYFUNCTION("""COMPUTED_VALUE"""),"Mayo") -> Mayo | N5: =IFERROR(__xludf.DUMMYFUNCTION("""COMPUTED_VALUE"""),"TRANSTOUR CIUDAD ROJA") -> TRANSTOUR CIUDAD ROJA | O5: =IFERROR(__xludf.DUMMYFUNCTION("""COMPUTED_VALUE"""),"NESTOR REINOSO GUAMAN") -> NESTOR REINOSO GUAMAN | Q5: =IFERROR(__xludf.DUMMYFUNCTION("""COMPUTED_VALUE"""),4.0) -> 4 | R5: =IFERROR(__xludf.DUMMYFUNCTION("""COMPUTED_VALUE"""),"8 HORAS") -> 8 HORAS | S5: =IFERROR(__xludf.DUMMYFUNCTION("""COMPUTED_VALUE"""),120.0) -> 120 | T5: =IFERROR(__xludf.DUMMYFUNCTION("""COMPUTED_VALUE"""),140.0) -> 140
A6: =IFERROR(__xludf.DUMMYFUNCTION("""COMPUTED_VALUE"""),"Histórico") -> Histórico | E6: =IFERROR(__xludf.DUMMYFUNCTION("""COMPUTED_VALUE"""),"Grupos") -> Grupos | I6: =IFERROR(__xludf.DUMMYFUNCTION("""COMPUTED_VALUE"""),"Junio") -> Junio | N6: =IFERROR(__xludf.DUMMYFUNCTION("""COMPUTED_VALUE"""),"TRANSTOUR CIUDAD ROJA") -> TRANSTOUR CIUDAD ROJA | O6: =IFERROR(__xludf.DUMMYFUNCTION("""COMPUTED_VALUE"""),"NESTOR REINOSO GUAMAN") -> NESTOR REINOSO GUAMAN | Q6: =IFERROR(__xludf.DUMMYFUNCTION("""COMPUTED_VALUE"""),8.0) -> 8 | R6: =IFERROR(__xludf.DUMMYFUNCTION("""COMPUTED_VALUE"""),"8 HORAS") -> 8 HORAS | S6: =IFERROR(__xludf.DUMMYFUNCTION("""COMPUTED_VALUE"""),130.0) -> 130 | T6: =IFERROR(__xludf.DUMMYFUNCTION("""COMPUTED_VALUE"""),150.0) -> 150
A7: =IFERROR(__xludf.DUMMYFUNCTION("""COMPUTED_VALUE"""),"Aventura") -> Aventura | I7: =IFERROR(__xludf.DUMMYFUNCTION("""COMPUTED_VALUE"""),"Julio") -> Julio | N7: =IFERROR(__xludf.DUMMYFUNCTION("""COMPUTED_VALUE"""),"TRANSTOUR CIUDAD ROJA") -> TRANSTOUR CIUDAD ROJA | O7: =IFERROR(__xludf.DUMMYFUNCTION("""COMPUTED_VALUE"""),"NESTOR REINOSO GUAMAN") -> NESTOR REINOSO GUAMAN | Q7: =IFERROR(__xludf.DUMMYFUNCTION("""COMPUTED_VALUE"""),12.0) -> 12 | R7: =IFERROR(__xludf.DUMMYFUNCTION("""COMPUTED_VALUE"""),"8 HORAS") -> 8 HORAS | S7: =IFERROR(__xludf.DUMMYFUNCTION("""COMPUTED_VALUE"""),160.0) -> 160 | T7: =IFERROR(__xludf.DUMMYFUNCTION("""COMPUTED_VALUE"""),180.0) -> 180
A8: =IFERROR(__xludf.DUMMYFUNCTION("""COMPUTED_VALUE"""),"Religión") -> Religión | I8: =IFERROR(__xludf.DUMMYFUNCTION("""COMPUTED_VALUE"""),"Agosto") -> Agosto | N8: =IFERROR(__xludf.DUMMYFUNCTION("""COMPUTED_VALUE"""),"TRANSTOUR CIUDAD ROJA") -> TRANSTOUR CIUDAD ROJA | O8: =IFERROR(__xludf.DUMMYFUNCTION("""COMPUTED_VALUE"""),"NESTOR REINOSO GUAMAN") -> NESTOR REINOSO GUAMAN | Q8: =IFERROR(__xludf.DUMMYFUNCTION("""COMPUTED_VALUE"""),16.0) -> 16 | R8: =IFERROR(__xludf.DUMMYFUNCTION("""COMPUTED_VALUE"""),"8 HORAS") -> 8 HORAS | S8: =IFERROR(__xludf.DUMMYFUNCTION("""COMPUTED_VALUE"""),180.0) -> 180 | T8: =IFERROR(__xludf.DUMMYFUNCTION("""COMPUTED_VALUE"""),200.0) -> 200
A9: =IFERROR(__xludf.DUMMYFUNCTION("""COMPUTED_VALUE"""),"Ecoturismo") -> Ecoturismo | I9: =IFERROR(__xludf.DUMMYFUNCTION("""COMPUTED_VALUE"""),"Septiembre") -> Septiembre | Q9: =IFERROR(__xludf.DUMMYFUNCTION("""COMPUTED_VALUE"""),4.0) -> 4 | R9: =IFERROR(__xludf.DUMMYFUNCTION("""COMPUTED_VALUE"""),"8 HORAS") -> 8 HORAS | S9: =IFERROR(__xludf.DUMMYFUNCTION("""COMPUTED_VALUE"""),90.0) -> 90 | T9: =IFERROR(__xludf.DUMMYFUNCTION("""COMPUTED_VALUE"""),75.0) -> 75
A10: =IFERROR(__xludf.DUMMYFUNCTION("""COMPUTED_VALUE"""),"Comunitario") -> Comunitario | I10: =IFERROR(__xludf.DUMMYFUNCTION("""COMPUTED_VALUE"""),"Octubre") -> Octubre
A11: =IFERROR(__xludf.DUMMYFUNCTION("""COMPUTED_VALUE"""),"Bienestar") -> Bienestar | I11: =IFERROR(__xludf.DUMMYFUNCTION("""COMPUTED_VALUE"""),"Noviembre") -> Noviembre
A12: =IFERROR(__xludf.DUMMYFUNCTION("""COMPUTED_VALUE"""),"Fotográfico") -> Fotográfico | I12: =IFERROR(__xludf.DUMMYFUNCTION("""COMPUTED_VALUE"""),"Diciembre") -> Diciembre
A13: =IFERROR(__xludf.DUMMYFUNCTION("""COMPUTED_VALUE"""),"Espiritual") -> Espiritual | I13: =IFERROR(__xludf.DUMMYFUNCTION("""COMPUTED_VALUE"""),"TODO EL AÑO") -> TODO EL AÑO
A14: =IFERROR(__xludf.DUMMYFUNCTION("""COMPUTED_VALUE"""),"Compras") -> Compras
A15: =IFERROR(__xludf.DUMMYFUNCTION("""COMPUTED_VALUE"""),"Nocturno") -> Nocturno

Sheet FICHA TÉCNICA
A1: FICHA TÉCNICA DE PRODUCTO TURÍSTICO: [NAT-004] — Paute: Dinosaurios, Naturaleza y Sabores
A2: 1. IDENTIFICACIÓN Y GENERALIDADES
A3: Código | B3: NAT-006 | C3: Dificultad | D3: Intermedio | E3: Duración | F3: 4 Horas
A4: Nombre Comercial | B4: Paute: Dinosaurios, Naturaleza y Sabores | C4: Categoría | D4: Naturaleza, Gastronomía | E4: Modalidad | F4: Compartido o Privado
A5: Destino Principal | B5: Cantón Paute (Azuay) | C5: Subcategoría | D5: Excursión Diurna, Gastronomia Local | E5: Mercado Objetivo | F5: Familias, Fotografos, Grupos
A6: Puntos Clave | B6: Jurassic Paute, Animal Paute, Parque Lineal y Monumento La Cuchara de Palo
A7: 2. DESCRIPCIÓN COMERCIAL
A8: Descripción Corta | B8: Aventura familiar de medio día (4 horas) desde Cuenca con salida a las 08:30 hacia el valle de Paute. Incluye Jurassic Paute, Animal Paute, el Parque Lineal y la Cuchara de Palo más grande del mundo por una tarifa de $35 USD por pasajero.
A9: Descripción Completa | B9: Excursión guiada de 4 horas diseñada para familias y visitantes de todas las edades con salida a las 08:30 desde Cuenca hacia el cantón Paute. El itinerario recorre el parque temático Jurassic Paute con dinosaurios animatrónicos, la reserva interactiva Animal Paute, el monumento y artesanías de La Cuchara de Palo (Récord Guinness) y las áreas verdes del Parque Lineal junto al río con degustación de la gastronomía típica, a una tarifa de $35 USD por persona.
A10: 📌 NOTA OPERATIVA Y COMERCIAL: El itinerario por horas, matriz tarifaria oficial, alcance de inclusiones/exclusiones y políticas de cancelación se encuentran centralizados y vigentes en la pestaña oficial 'FICHA TOUR'.
A11: 3. DETALLE DE ATRACTIVOS Y GUION INTERPRETATIVO PARA GUÍAS
A12: N° | B12: Atractivo Turístico | C12: Altitud | D12: Enfoque Principal | E12: Guion Interpretativo / Dato Clave | F12: Recomendaciones Operativas / Servicios
A13: 1 | B13: Jurassic Paute | C13: 2.150 msnm | D13: Recreación Temática y Paleontología | E13: Exhibición de dinosaurios animatrónicos a escala real con sonido, senderos temáticos y fósiles educativos. | F13: Calzado cómodo para caminata, asistencia a niños en senderos y batería cargada para fotografía.
A14: 2 | B14: Animal Paute | C14: 2.180 msnm | D14: Contacto con la Naturaleza y Fauna | E14: Espacio de interacción responsable con animales de granja y fauna, fomentando la conservación y el aprendizaje lúdico. | F14: Respetar normas de interacción animal, desinfección de manos en estaciones y supervisión de menores.
A15: 3 | B15: Monumento La Cuchara de Palo | C15: 2.120 msnm | D15: Cultura, Tradición y Récord Guinness | E15: Símbolo de la maestría artesanal de Paute, reconocido por el Récord Guinness como la cuchara de madera más grande del mundo. | F15: Parada fotográfica grupal, visita a talleres locales de madera labrada y uso de efectivo en denominaciones bajas.
A16: 4 | B16: Parque Lineal y Gastronomía Local | C16: 2.100 msnm | D16: Paisajismo Ribereño y Tradición Culinaria | E16: Paseo por las orillas del río Paute integrado a la degustación de platos típicos vallunos (cuy, fritada, conservas y dulces). | F16: Paseo llano y accesible para toda edad, disponibilidad de baterías sanitarias y tiempo para degustación.
A18: 4. MÉTRICAS TÉCNICAS DE TERRENO Y ESFUERZO FÍSICO
A19: Distancia Total Caminata | B19: 1.5 - 2.5 km (recorridos temáticos) | C19: Desnivel Positivo (+) | D19: +45 m | E19: Desnivel Negativo (-) | F19: -45 m
A20: Altitud Mínima / Máxima | B20: 2.100 msnm — 2.250 msnm | C20: Tipo de Sendero / Suelo | D20: Adoquín, césped, tierra compacta y pasarelas llanas | E20: Pendiente Máxima | F20: Baja / Suave (3% - 8%)
A21: Clima Predominante | B21: Templado / Cálido de valle interandino | C21: Rango de Temperatura | D21: 14°C a 24°C | E21: Índice UV Estimado | F21: Moderado a Alto (6 - 9)
A22: Exposición Solar y Viento | B22: Exposición moderada a sol de valle, brisa ligera | C22: Nivel Exigencia Física | D22: Bajo / Familiar (apto para todo público y niños) | E22: Tiempo Efectivo Caminata | F22: 1.5 a 2 horas fraccionadas
A23: Equipamiento de Terreno | B23: Calzado deportivo cómodo, ropa ligera para clima templado, protección solar (gorra y bloqueador), abrigo ligero para la tarde e hidratación personal.
A25: 5. PERFIL Y REQUISITOS DEL PERSONAL DE RUTA
A26: Licencia Guía Exigida | B26: Guia Nacional | C26: Certificación Primeros Auxilios | D26: Primeros Auxilios Básicos / RCP Vigente | E26: Ratio Guía / Pasajeros | F26: 1:16 pasajeros
A27: Idiomas del Personal | B27: Español | C27: Perfil Conductor / Chofer | D27: Licencia Profesional Tipo D o C | E27: Competencias Técnicas Clave | F27: Dinámica de grupos familiares, atención infantil y servicio al cliente
A28: Código de Conducta en Ruta | B28: Puntualidad estricta en traslados, asistencia a niños y adultos mayores, respeto a las normas de los parques y cordialidad en todo momento.
A30: 6. SEGURIDAD, PRIMEROS AUXILIOS Y PROTOCOLO DE EVACUACIÓN
A31: Botiquín Obligatorio a Bordo | B31: Botiquín básico: antisépticos, gasas estériles, vendas elásticas, apósitos, analgésicos pediátricos y adultos, antihistamínicos, repelente y sales de hidratación oral.
A32: Cobertura Móvil / Celular | B32: CLARO (vía principal), TIGO (vía principal), CNT (vía principal) | C32: Telecomunicaciones de Emergencia | D32: Telefonía Celular / Red 4G LTE
A33: Punto de Escape 1 (Km 0-25) | B33: Retorno Vía Rápida Cuenca - Azogues - Paute | C33: Centro de Salud de Apoyo | D33: Centro de Salud Tipo C El Cabo / Paute | E33: Tiempo Estimado Evacuación | F33: 10 - 15 minutos
A34: Punto de Escape 2 (Casco Paute) | B34: Hospital Básico Cantonal de Paute | C34: Hospital de Referencia Mayor | D34: Hospital Vicente Corral Moscoso (Cuenca) | E34: Tiempo Estimado Evacuación | F34: 35 - 45 minutos
A35: Línea de Emergencia Principal | B35: ECU 911 | Base Central: +593 99 590 0614 | C35: Protocolo Emergencias Médicas | D35: Primeros auxilios inmediatos, estabilización del paciente, notificación a ECU 911 y traslado prioritario a centro asistencial.
A36: Póliza de Asistencia y Seguro | B36: Seguro de accidentes personales y responsabilidad civil en transporte turístico vigente para todos los pasajeros registrados en el manifiesto.

Sheet FICHA TOUR
A2: PLANTILLA MAESTRA DE CREACIÓN DE TOUR — CÓNDOR EXPEDITIONS
A3: Código / Nombre: | B3: =CONCATENATE(B6," ",B7) -> NAT-006 Paute: Dinosaurios, Naturaleza y Sabores | C3: Versión / Fecha: | D3: v2.7 | [DD/MM/AAAA] | E3: Área: Operaciones
A5: 1. DATOS BÁSICOS DEL TOUR
A6: Código / ID del Tour | B6: ='FICHA TÉCNICA'!B3 -> NAT-006 | C6: Categoría | D6: ='FICHA TÉCNICA'!D4 -> Naturaleza, Gastronomía
A7: Nombre Comercial | B7: ='FICHA TÉCNICA'!B4 -> Paute: Dinosaurios, Naturaleza y Sabores | C7: Dificultad | D7: ='FICHA TÉCNICA'!D3 -> Intermedio
A8: Descripción Breve | B8: ='FICHA TÉCNICA'!B8 -> Aventura familiar de medio día (4 horas) desde Cuenca con salida a las 08:30 hacia el valle de Paute. Incluye Jurassic Paute, Animal Paute, el Parque Lineal y la Cuchara de Palo más grande del mundo por una tarifa de $35 USD por pasajero.
A9: Duración Estimada Tour | B9: ='FICHA TÉCNICA'!F3 -> 4 Horas | C9: Público Objetivo | D9: ='FICHA TÉCNICA'!F5 -> Familias, Fotografos, Grupos
A10: Temporada | B10: TODO EL AÑO | C10: Idiomas Disponibles | D10: ='FICHA TÉCNICA'!$B$27 -> Español
A12: 2. LOGÍSTICA COMPLETA DE OPERACIÓN
A13: Punto de Salida | B13: Parque Calderón / Hotel Ensueños | C13: Lugar de Retorno | D13: Parque Calderón / Hotel Ensueños
A14: Días de Operación | B14: Viernes, Sábado y Domingo | C14: Duración Translado Total | D14: Aprox. 1.5 horas (45 min por trayecto)
A15: Flota Requerida | B15: Van 12-16 pax | C15: Capacidad Minima Rentable | D15: 4 pasajeros (Mínimo de operación)
A16: Paradas Intermedias | B16: ='FICHA TÉCNICA'!B6 -> Jurassic Paute, Animal Paute, Parque Lineal y Monumento La Cuchara de Palo
A17: Horario de Salida | B17: Mañana: 08:30, Tarde: 14:00 | C17: Responsable Operativo | D17: Coordinador de Operaciones / Guía Líder
A18: Mapa del Recorrido | B18: Ruta Cuenca – El Descanso – Paute (aprox. 42 km / 45 min por vía rápida E40). Circuito turístico por atractivos cantonales.
A20: 3. ITINERARIO Y OPERACIONES DEL RECORRIDO
A21: Duración | B21: Actividad | D21: Lugar / Parada | E21: Responsable
A22: 15 min | B22: Encuentro de pasajeros, registro y traslado hacia Paute | D22: Parque Calderón / Hotel Ensueños | E22: Guía / Conductor
A23: 1 hora | B23: Recorrido guiado temático con réplicas de dinosaurios y fotos | D23: Parque Temático Jurassic Paute | E23: Guía Acreditado
A24: 1 hora | B24: Interacción con especies de fauna protegida y contacto natural | D24: Animal Paute (Granja y Fauna) | E24: Guía / Personal Animal Paute
A25: 45 min | B25: Visita a la escultura Récord Guinness y talleres de madera labrada | D25: Monumento La Cuchara de Palo | E25: Guía Acreditado
A26: 45 min | B26: Paseo escénico, descanso y fotografías junto a las orillas del río | D26: Parque Lineal de Paute | E26: Guía Acreditado
A27: 45 min | B27: Almuerzo típico y degustación de dulces y conservas del cantón | D27: Restaurante Local / Paute Centro | E27: Guía / Proveedor Gastronómico
A28: 45 min | B28: Traslado de retorno a Cuenca y desembarque de pasajeros | D28: Retorno a Parque Calderón | E28: Conductor / Guía
A30: 3.2 CONDICIONES DE OPERACIÓN Y POLÍTICAS DE CANCELACIÓN
A31: Parámetro / Concepto | B31: Condición Operativa / Término del Servicio | D31: Detalle / Política Aplicable
A32: Mínimo de Pasajeros | B32: Salidas compartidas operan con un mínimo de 4 pasajeros confirmados. | D32: Si no se alcanza el cupo, se ofrece reprogramación o tarifa privada.
A33: Reserva y Anticipo | B33: Pago del 50% requerido al momento de confirmar la reserva. | D33: Saldo restante liquidable hasta 24 horas antes de la salida programada.
A34: Cancelación Previa (>48h) | B34: Cancelaciones con más de 48 horas de anticipación reciben reembolso del 100%. | D34: Se deducen únicamente gastos administrativos y bancarios directos.
A35: Cancelación Tardía (<24h) | B35: Cancelaciones con menos de 24 horas aplican penalización del 100%. | D35: Aplica igualmente en situaciones de no presentación al tour (No-show).
A36: Condiciones Climáticas | B36: La ruta opera con normalidad bajo lluvia ligera típica de montaña. | D36: Ante temporales extremos o niebla que afecte la seguridad, se adapta ruta.
A37: Cierre de Vías / Imprevistos | B37: Interrupciones o cierres en la vía Cuenca–El Descanso–Paute. | D37: Opción de reprogramar fecha o recorrido alternativo en el valle.
A38: Marco de Cobertura | B38: Operación bajo normativa turística cantonal de Paute y MINTUR. | D38: Asistencia al viajero y seguro de viaje activo en todo el recorrido.
A40: 4. INCLUSIONES Y EXCLUSIONES DEL SERVICIO
A41: 🎒 INCLUSIONES | C41: 🚫 EXCLUSIONES
A42: • Transporte turístico de ida y vuelta en van climatizada con chofer profesional | C42: • Propinas a guías y choferes (voluntarias / opcionales)
A43: • Guía profesional de turismo acreditado en español | C43: • Gastos personales, compras de artesanías en madera y recuerdos
A44: • Entradas oficiales a Jurassic Paute y Animal Paute | C44: • Bebidas alcohólicas y consumos no contemplados en el menú acordado
A45: • Alimentación completa: almuerzo tradicional pauteño y refrigerio de agua | C45: • Actividades opcionales, desvíos o traslados fuera de itinerario
A46: • Botiquín de primeros auxilios y seguro de asistencia médica en viaje | C46: • Seguros especiales para actividades no programadas
...

Sheet MODELOS DE COSTOS
A2: ANÁLISIS DE VIABILIDAD FINANCIERA Y FIJACIÓN DE PRECIOS — CÓNDOR EXPEDITIONS
A3: 6.1 MODELOS DE COSTOS POR OCUPACIÓN
A4: Ocupación \ Costos PAX ($) | B4: TRUE | C4: TRUE | D4: TRUE | E4: TRUE | F4: TRUE | G4: TRUE | H4: TRUE | I4: TRUE | J4: TRUE
A5: Rubro de Costo | B5: 1 | C5: 2 | D5: 3 | E5: 4 | F5: 5 | G5: 6 | H5: 7 | I5: 8 | J5: 9 | K5: Observación / Detalle
A6: Transporte | B6: =IFERROR(__xludf.DUMMYFUNCTION("IF(B4,IFERROR(INDEX(FILTER('DB CONECTOR'!$S$1:$S$8, 'DB CONECTOR'!$N$1:$N$8=$B$45, 'DB CONECTOR'!$R$1:$R$8=$B$46, 'DB CONECTOR'!$Q$1:$Q$8>=B5), 1), 0),IFERROR(INDEX(FILTER('DB CONECTOR'!$T$1:$T$8, 'DB CONECTOR'!$N$1:$N$8=$B$45, 'DB CONECTOR'!$R$1:$R$8=$B$"&"46, 'DB CONECTOR'!$Q$1:$Q$8>=B5), 1), 0))"),80.0) -> 80 | C6: =IFERROR(__xludf.DUMMYFUNCTION("IF(C4,IFERROR(INDEX(FILTER('DB CONECTOR'!$S$1:$S$8, 'DB CONECTOR'!$N$1:$N$8=$B$45, 'DB CONECTOR'!$R$1:$R$8=$B$46, 'DB CONECTOR'!$Q$1:$Q$8>=C5), 1), 0),IFERROR(INDEX(FILTER('DB CONECTOR'!$T$1:$T$8, 'DB CONECTOR'!$N$1:$N$8=$B$45, 'DB CONECTOR'!$R$1:$R$8=$B$"&"46, 'DB CONECTOR'!$Q$1:$Q$8>=C5), 1), 0))"),80.0) -> 80 | D6: =IFERROR(__xludf.DUMMYFUNCTION("IF(D4,IFERROR(INDEX(FILTER('DB CONECTOR'!$S$1:$S$8, 'DB CONECTOR'!$N$1:$N$8=$B$45, 'DB CONECTOR'!$R$1:$R$8=$B$46, 'DB CONECTOR'!$Q$1:$Q$8>=D5), 1), 0),IFERROR(INDEX(FILTER('DB CONECTOR'!$T$1:$T$8, 'DB CONECTOR'!$N$1:$N$8=$B$45, 'DB CONECTOR'!$R$1:$R$8=$B$"&"46, 'DB CONECTOR'!$Q$1:$Q$8>=D5), 1), 0))"),80.0) -> 80 | E6: =IFERROR(__xludf.DUMMYFUNCTION("IF(E4,IFERROR(INDEX(FILTER('DB CONECTOR'!$S$1:$S$8, 'DB CONECTOR'!$N$1:$N$8=$B$45, 'DB CONECTOR'!$R$1:$R$8=$B$46, 'DB CONECTOR'!$Q$1:$Q$8>=E5), 1), 0),IFERROR(INDEX(FILTER('DB CONECTOR'!$T$1:$T$8, 'DB CONECTOR'!$N$1:$N$8=$B$45, 'DB CONECTOR'!$R$1:$R$8=$B$"&"46, 'DB CONECTOR'!$Q$1:$Q$8>=E5), 1), 0))"),80.0) -> 80 | F6: =IFERROR(__xludf.DUMMYFUNCTION("IF(F4,IFERROR(INDEX(FILTER('DB CONECTOR'!$S$1:$S$8, 'DB CONECTOR'!$N$1:$N$8=$B$45, 'DB CONECTOR'!$R$1:$R$8=$B$46, 'DB CONECTOR'!$Q$1:$Q$8>=F5), 1), 0),IFERROR(INDEX(FILTER('DB CONECTOR'!$T$1:$T$8, 'DB CONECTOR'!$N$1:$N$8=$B$45, 'DB CONECTOR'!$R$1:$R$8=$B$"&"46, 'DB CONECTOR'!$Q$1:$Q$8>=F5), 1), 0))"),90.0) -> 90 | G6: =IFERROR(__xludf.DUMMYFUNCTION("IF(G4,IFERROR(INDEX(FILTER('DB CONECTOR'!$S$1:$S$8, 'DB CONECTOR'!$N$1:$N$8=$B$45, 'DB CONECTOR'!$R$1:$R$8=$B$46, 'DB CONECTOR'!$Q$1:$Q$8>=G5), 1), 0),IFERROR(INDEX(FILTER('DB CONECTOR'!$T$1:$T$8, 'DB CONECTOR'!$N$1:$N$8=$B$45, 'DB CONECTOR'!$R$1:$R$8=$B$"&"46, 'DB CONECTOR'!$Q$1:$Q$8>=G5), 1), 0))"),90.0) -> 90 | H6: =IFERROR(__xludf.DUMMYFUNCTION("IF(H4,IFERROR(INDEX(FILTER('DB CONECTOR'!$S$1:$S$8, 'DB CONECTOR'!$N$1:$N$8=$B$45, 'DB CONECTOR'!$R$1:$R$8=$B$46, 'DB CONECTOR'!$Q$1:$Q$8>=H5), 1), 0),IFERROR(INDEX(FILTER('DB CONECTOR'!$T$1:$T$8, 'DB CONECTOR'!$N$1:$N$8=$B$45, 'DB CONECTOR'!$R$1:$R$8=$B$"&"46, 'DB CONECTOR'!$Q$1:$Q$8>=H5), 1), 0))"),90.0) -> 90 | I6: =IFERROR(__xludf.DUMMYFUNCTION("IF(I4,IFERROR(INDEX(FILTER('DB CONECTOR'!$S$1:$S$8, 'DB CONECTOR'!$N$1:$N$8=$B$45, 'DB CONECTOR'!$R$1:$R$8=$B$46, 'DB CONECTOR'!$Q$1:$Q$8>=I5), 1), 0),IFERROR(INDEX(FILTER('DB CONECTOR'!$T$1:$T$8, 'DB CONECTOR'!$N$1:$N$8=$B$45, 'DB CONECTOR'!$R$1:$R$8=$B$"&"46, 'DB CONECTOR'!$Q$1:$Q$8>=I5), 1), 0))"),120.0) -> 120 | J6: =IFERROR(__xludf.DUMMYFUNCTION("IF(J4,IFERROR(INDEX(FILTER('DB CONECTOR'!$S$1:$S$8, 'DB CONECTOR'!$N$1:$N$8=$B$45, 'DB CONECTOR'!$R$1:$R$8=$B$46, 'DB CONECTOR'!$Q$1:$Q$8>=J5), 1), 0),IFERROR(INDEX(FILTER('DB CONECTOR'!$T$1:$T$8, 'DB CONECTOR'!$N$1:$N$8=$B$45, 'DB CONECTOR'!$R$1:$R$8=$B$"&"46, 'DB CONECTOR'!$Q$1:$Q$8>=J5), 1), 0))"),120.0) -> 120 | K6: Combustible + peajes + chofer
A7: Guía especializado | B7: =IF(B5/16>1, IF((SUM(B6, B8:B16) + VLOOKUP($B$46, 'DB CONECTOR'!$K$1:$L$2, 2, FALSE)*2)/B5 <= $B$44, VLOOKUP($B$46, 'DB CONECTOR'!$K$1:$L$2, 2, FALSE)*2, 0), IF((SUM(B6, B8:B16) + VLOOKUP($B$46, 'DB CONECTOR'!$K$1:$L$2, 2, FALSE))/B5 <= $B$44, VLOOKUP($B$46, 'DB CONECTOR'!$K$1:$L$2, 2, FALSE), 0)) -> 0 | C7: =IF(C5/16>1, IF((SUM(C6, C8:C16) + VLOOKUP($B$46, 'DB CONECTOR'!$K$1:$L$2, 2, FALSE)*2)/C5 <= $B$44, VLOOKUP($B$46, 'DB CONECTOR'!$K$1:$L$2, 2, FALSE)*2, 0), IF((SUM(C6, C8:C16) + VLOOKUP($B$46, 'DB CONECTOR'!$K$1:$L$2, 2, FALSE))/C5 <= $B$44, VLOOKUP($B$46, 'DB CONECTOR'!$K$1:$L$2, 2, FALSE), 0)) -> 0 | D7: =IF(D5/16>1, IF((SUM(D6, D8:D16) + VLOOKUP($B$46, 'DB CONECTOR'!$K$1:$L$2, 2, FALSE)*2)/D5 <= $B$44, VLOOKUP($B$46, 'DB CONECTOR'!$K$1:$L$2, 2, FALSE)*2, 0), IF((SUM(D6, D8:D16) + VLOOKUP($B$46, 'DB CONECTOR'!$K$1:$L$2, 2, FALSE))/D5 <= $B$44, VLOOKUP($B$46, 'DB CONECTOR'!$K$1:$L$2, 2, FALSE), 0)) -> 0 | E7: =IF(E5/16>1, IF((SUM(E6, E8:E16) + VLOOKUP($B$46, 'DB CONECTOR'!$K$1:$L$2, 2, FALSE)*2)/E5 <= $B$44, VLOOKUP($B$46, 'DB CONECTOR'!$K$1:$L$2, 2, FALSE)*2, 0), IF((SUM(E6, E8:E16) + VLOOKUP($B$46, 'DB CONECTOR'!$K$1:$L$2, 2, FALSE))/E5 <= $B$44, VLOOKUP($B$46, 'DB CONECTOR'!$K$1:$L$2, 2, FALSE), 0)) -> 0 | F7: =IF(F5/16>1, IF((SUM(F6, F8:F16) + VLOOKUP($B$46, 'DB CONECTOR'!$K$1:$L$2, 2, FALSE)*2)/F5 <= $B$44, VLOOKUP($B$46, 'DB CONECTOR'!$K$1:$L$2, 2, FALSE)*2, 0), IF((SUM(F6, F8:F16) + VLOOKUP($B$46, 'DB CONECTOR'!$K$1:$L$2, 2, FALSE))/F5 <= $B$44, VLOOKUP($B$46, 'DB CONECTOR'!$K$1:$L$2, 2, FALSE), 0)) -> 40 | G7: =IF(G5/16>1, IF((SUM(G6, G8:G16) + VLOOKUP($B$46, 'DB CONECTOR'!$K$1:$L$2, 2, FALSE)*2)/G5 <= $B$44, VLOOKUP($B$46, 'DB CONECTOR'!$K$1:$L$2, 2, FALSE)*2, 0), IF((SUM(G6, G8:G16) + VLOOKUP($B$46, 'DB CONECTOR'!$K$1:$L$2, 2, FALSE))/G5 <= $B$44, VLOOKUP($B$46, 'DB CONECTOR'!$K$1:$L$2, 2, FALSE), 0)) -> 40 | H7: =IF(H5/16>1, IF((SUM(H6, H8:H16) + VLOOKUP($B$46, 'DB CONECTOR'!$K$1:$L$2, 2, FALSE)*2)/H5 <= $B$44, VLOOKUP($B$46, 'DB CONECTOR'!$K$1:$L$2, 2, FALSE)*2, 0), IF((SUM(H6, H8:H16) + VLOOKUP($B$46, 'DB CONECTOR'!$K$1:$L$2, 2, FALSE))/H5 <= $B$44, VLOOKUP($B$46, 'DB CONECTOR'!$K$1:$L$2, 2, FALSE), 0)) -> 40 | I7: =IF(I5/16>1, IF((SUM(I6, I8:I16) + VLOOKUP($B$46, 'DB CONECTOR'!$K$1:$L$2, 2, FALSE)*2)/I5 <= $B$44, VLOOKUP($B$46, 'DB CONECTOR'!$K$1:$L$2, 2, FALSE)*2, 0), IF((SUM(I6, I8:I16) + VLOOKUP($B$46, 'DB CONECTOR'!$K$1:$L$2, 2, FALSE))/I5 <= $B$44, VLOOKUP($B$46, 'DB CONECTOR'!$K$1:$L$2, 2, FALSE), 0)) -> 40 | J7: =IF(J5/16>1, IF((SUM(J6, J8:J16) + VLOOKUP($B$46, 'DB CONECTOR'!$K$1:$L$2, 2, FALSE)*2)/J5 <= $B$44, VLOOKUP($B$46, 'DB CONECTOR'!$K$1:$L$2, 2, FALSE)*2, 0), IF((SUM(J6, J8:J16) + VLOOKUP($B$46, 'DB CONECTOR'!$K$1:$L$2, 2, FALSE))/J5 <= $B$44, VLOOKUP($B$46, 'DB CONECTOR'!$K$1:$L$2, 2, FALSE), 0)) -> 40 | K7: Tipo: Naturalista acreditado
A8: Ingreso a Destinos | B8: 8 | C8: =$B$8*C5 -> 16 | D8: =$B$8*D5 -> 24 | E8: =$B$8*E5 -> 32 | F8: =$B$8*F5 -> 40 | G8: =$B$8*G5 -> 48 | H8: =$B$8*H5 -> 56 | I8: =$B$8*I5 -> 64 | J8: =$B$8*J5 -> 72 | K8: Entradas a reserva / atractivo | M8: `
A9: Actividades | B9: 0 | C9: =$B$9*C5 -> 0 | D9: =$B$9*D5 -> 0 | E9: =$B$9*E5 -> 0 | F9: =$B$9*F5 -> 0 | G9: =$B$9*G5 -> 0 | H9: =$B$9*H5 -> 0 | I9: =$B$9*I5 -> 0 | J9: =$B$9*J5 -> 0 | K9: Juegos, Recreaciones, Etc
A10: Kit de Primeros Auxilio | B10: 0 | C10: =$B$10*C5 -> 0 | D10: =$B$10*D5 -> 0 | E10: =$B$10*E5 -> 0 | F10: =$B$10*F5 -> 0 | G10: =$B$10*G5 -> 0 | H10: =$B$10*H5 -> 0 | I10: =$B$10*I5 -> 0 | J10: =$B$10*J5 -> 0 | K10: Pastillas para el mareo, estomago y demas
A11: Kit de Dulces | B11: 0 | C11: =$B$11*C5 -> 0 | D11: =$B$11*D5 -> 0 | E11: =$B$11*E5 -> 0 | F11: =$B$11*F5 -> 0 | G11: =$B$11*G5 -> 0 | H11: =$B$11*H5 -> 0 | I11: =$B$11*I5 -> 0 | J11: =$B$11*J5 -> 0 | K11: Kit de Dulces
A12: Hidratacion | B12: 0 | C12: =$B$12*C5 -> 0 | D12: =$B$12*D5 -> 0 | E12: =$B$12*E5 -> 0 | F12: =$B$12*F5 -> 0 | G12: =$B$12*G5 -> 0 | H12: =$B$12*H5 -> 0 | I12: =$B$12*I5 -> 0 | J12: =$B$12*J5 -> 0 | K12: Botella de Agua
A13: Alimentacion | B13: 0 | C13: =$B$13*C5 -> 0 | D13: =$B$13*D5 -> 0 | E13: =$B$13*E5 -> 0 | F13: =$B$13*F5 -> 0 | G13: =$B$13*G5 -> 0 | H13: =$B$13*H5 -> 0 | I13: =$B$13*I5 -> 0 | J13: =$B$13*J5 -> 0 | K13: Alimentacion si esta incluida
A14: Seguro de viaje | B14: 0 | C14: =$B$14*C5 -> 0 | D14: =$B$14*D5 -> 0 | E14: =$B$14*E5 -> 0 | F14: =$B$14*F5 -> 0 | G14: =$B$14*G5 -> 0 | H14: =$B$14*H5 -> 0 | I14: =$B$14*I5 -> 0 | J14: =$B$14*J5 -> 0 | K14: Valor del seguro
A15: Patente de Tour | B15: 0 | C15: =$B$15*C5 -> 0 | D15: =$B$15*D5 -> 0 | E15: =$B$15*E5 -> 0 | F15: =$B$15*F5 -> 0 | G15: =$B$15*G5 -> 0 | H15: =$B$15*H5 -> 0 | I15: =$B$15*I5 -> 0 | J15: =$B$15*J5 -> 0 | K15: Costo de la patente por pax
A16: Otros Costos | B16: 0 | C16: =$B$16*C5 -> 0 | D16: =$B$16*D5 -> 0 | E16: =$B$16*E5 -> 0 | F16: =$B$16*F5 -> 0 | G16: =$B$16*G5 -> 0 | H16: =$B$16*H5 -> 0 | I16: =$B$16*I5 -> 0 | J16: =$B$16*J5 -> 0 | K16: Admin 15%, Marketing 10%, Tech 5%
A17: TOTAL COSTO X PAX | B17: =SUM(B6:B16) -> 88 | C17: =SUM(C6:C16) -> 96 | D17: =SUM(D6:D16) -> 104 | E17: =SUM(E6:E16) -> 112 | F17: =SUM(F6:F16) -> 170 | G17: =SUM(G6:G16) -> 178 | H17: =SUM(H6:H16) -> 186 | I17: =SUM(I6:I16) -> 224 | J17: =SUM(J6:J16) -> 232 | K17: Costo operativo total base
A18: COSTO UNITARIO | B18: =B17/B5 -> 88 | C18: =C17/C5 -> 48 | D18: =D17/D5 -> 34.666667 | E18: =E17/E5 -> 28 | F18: =F17/F5 -> 34 | G18: =G17/G5 -> 29.666667 | H18: =H17/H5 -> 26.571429 | I18: =I17/I5 -> 28 | J18: =J17/J5 -> 25.777778 | K18: Costo operativo por persona
A19: =CONCATENATE("UTILIDAD ",TEXT($B$43,"0%")) -> UTILIDAD 30% | B19: =IF(B18<=$B$44,$B$44,IF(MROUND(B18 * (1 + $B$43), 5) > $B$44, 0, $B$44)) -> 0 | C19: =IF(C18<=$B$44,$B$44,IF(MROUND(C18 * (1 + $B$43), 5) > $B$44, 0, $B$44)) -> 0 | D19: =IF(D18<=$B$44,$B$44,IF(MROUND(D18 * (1 + $B$43), 5) > $B$44, 0, $B$44)) -> 35 | E19: =IF(E18<=$B$44,$B$44,IF(MROUND(E18 * (1 + $B$43), 5) > $B$44, 0, $B$44)) -> 35 | F19: =IF(F18<=$B$44,$B$44,IF(MROUND(F18 * (1 + $B$43), 5) > $B$44, 0, $B$44)) -> 35 | G19: =IF(G18<=$B$44,$B$44,IF(MROUND(G18 * (1 + $B$43), 5) > $B$44, 0, $B$44)) -> 35 | H19: =IF(H18<=$B$44,$B$44,IF(MROUND(H18 * (1 + $B$43), 5) > $B$44, 0, $B$44)) -> 35 | I19: =IF(I18<=$B$44,$B$44,IF(MROUND(I18 * (1 + $B$43), 5) > $B$44, 0, $B$44)) -> 35 | J19: =IF(J18<=$B$44,$B$44,IF(MROUND(J18 * (1 + $B$43), 5) > $B$44, 0, $B$44)) -> 35 | K19: =CONCATENATE("Aumentar ",TEXT($B$43,"0%")," de ganancia") -> Aumentar 30% de ganancia
A20: UTILIDAD ALCANZADA | B20: =IF(B19<=$B$44,IFERROR((B19 - B18) / B18, 0),0) -> -1 | C20: =IF(C19<=$B$44,IFERROR((C19 - C18) / C18, 0),0) -> -1 | D20: =IF(D19<=$B$44,IFERROR((D19 - D18) / D18, 0),0) -> 0.0096153846 | E20: =IF(E19<=$B$44,IFERROR((E19 - E18) / E18, 0),0) -> 0.25 | F20: =IF(F19<=$B$44,IFERROR((F19 - F18) / F18, 0),0) -> 0.029411765 | G20: =IF(G19<=$B$44,IFERROR((G19 - G18) / G18, 0),0) -> 0.17977528 | H20: =IF(H19<=$B$44,IFERROR((H19 - H18) / H18, 0),0) -> 0.3172043 | I20: =IF(I19<=$B$44,IFERROR((I19 - I18) / I18, 0),0) -> 0.25 | J20: =IF(J19<=$B$44,IFERROR((J19 - J18) / J18, 0),0) -> 0.35775862 | K20: Valor Real Alcanzado
A22: Ocupación \ Costos PAX ($) | B22: TRUE | C22: TRUE | D22: TRUE | E22: TRUE | F22: TRUE | G22: TRUE | H22: TRUE | I22: TRUE | J22: TRUE
A23: Rubro de Costo | B23: 10 | C23: 11 | D23: 12 | E23: 13 | F23: 14 | G23: 15 | H23: 16 | I23: 24 | J23: 44 | K23: Observación / Detalle
A24: Transporte | B24: =IFERROR(__xludf.DUMMYFUNCTION("IF(B22,IFERROR(INDEX(FILTER('DB CONECTOR'!$S$1:$S$8, 'DB CONECTOR'!$N$1:$N$8=$B$45, 'DB CONECTOR'!$R$1:$R$8=$B$46, 'DB CONECTOR'!$Q$1:$Q$8>=B23), 1), 0),IFERROR(INDEX(FILTER('DB CONECTOR'!$T$1:$T$8, 'DB CONECTOR'!$N$1:$N$8=$B$45, 'DB CONECTOR'!$R$1:$R$8=$"&"B$46, 'DB CONECTOR'!$Q$1:$Q$8>=B23), 1), 0))"),120.0) -> 120 | C24: =IFERROR(__xludf.DUMMYFUNCTION("IFERROR(INDEX(FILTER('DB CONECTOR'!$T$1:$T$8, 'DB CONECTOR'!$N$1:$N$8=$B$45, 'DB CONECTOR'!$R$1:$R$8=$B$46, 'DB CONECTOR'!$Q$1:$Q$8>=C23), 1), 0)"),150.0) -> 150 | D24: =IFERROR(__xludf.DUMMYFUNCTION("IFERROR(INDEX(FILTER('DB CONECTOR'!$T$1:$T$8, 'DB CONECTOR'!$N$1:$N$8=$B$45, 'DB CONECTOR'!$R$1:$R$8=$B$46, 'DB CONECTOR'!$Q$1:$Q$8>=D23), 1), 0)"),150.0) -> 150 | E24: =IFERROR(__xludf.DUMMYFUNCTION("IFERROR(INDEX(FILTER('DB CONECTOR'!$T$1:$T$8, 'DB CONECTOR'!$N$1:$N$8=$B$45, 'DB CONECTOR'!$R$1:$R$8=$B$46, 'DB CONECTOR'!$Q$1:$Q$8>=E23), 1), 0)"),180.0) -> 180 | F24: =IFERROR(__xludf.DUMMYFUNCTION("IFERROR(INDEX(FILTER('DB CONECTOR'!$T$1:$T$8, 'DB CONECTOR'!$N$1:$N$8=$B$45, 'DB CONECTOR'!$R$1:$R$8=$B$46, 'DB CONECTOR'!$Q$1:$Q$8>=F23), 1), 0)"),180.0) -> 180 | G24: =IFERROR(__xludf.DUMMYFUNCTION("IFERROR(INDEX(FILTER('DB CONECTOR'!$T$1:$T$8, 'DB CONECTOR'!$N$1:$N$8=$B$45, 'DB CONECTOR'!$R$1:$R$8=$B$46, 'DB CONECTOR'!$Q$1:$Q$8>=G23), 1), 0)"),180.0) -> 180 | H24: =IFERROR(__xludf.DUMMYFUNCTION("IFERROR(INDEX(FILTER('DB CONECTOR'!$T$1:$T$8, 'DB CONECTOR'!$N$1:$N$8=$B$45, 'DB CONECTOR'!$R$1:$R$8=$B$46, 'DB CONECTOR'!$Q$1:$Q$8>=H23), 1), 0)"),180.0) -> 180 | I24: =IFERROR(__xludf.DUMMYFUNCTION("IFERROR(INDEX(FILTER('DB CONECTOR'!$T$1:$T$8, 'DB CONECTOR'!$N$1:$N$8=$B$45, 'DB CONECTOR'!$R$1:$R$8=$B$46, 'DB CONECTOR'!$Q$1:$Q$8>=I23), 1), 0)"),0.0) -> 0 | J24: =IFERROR(__xludf.DUMMYFUNCTION("IFERROR(INDEX(FILTER('DB CONECTOR'!$T$1:$T$8, 'DB CONECTOR'!$N$1:$N$8=$B$45, 'DB CONECTOR'!$R$1:$R$8=$B$46, 'DB CONECTOR'!$Q$1:$Q$8>=J23), 1), 0)"),0.0) -> 0 | K24: =K6 -> Combustible + peajes + chofer
A25: Guía especializado | B25: =IF(B23/16>1, IF((SUM(B24, B26:B34) + VLOOKUP($B$46, 'DB CONECTOR'!$K$1:$L$2, 2, FALSE)*2)/B23 <= $B$44, VLOOKUP($B$46, 'DB CONECTOR'!$K$1:$L$2, 2, FALSE)*2, 0), IF((SUM(B24, B26:B34) + VLOOKUP($B$46, 'DB CONECTOR'!$K$1:$L$2, 2, FALSE))/B23 <= $B$44, VLOOKUP($B$46, 'DB CONECTOR'!$K$1:$L$2, 2, FALSE), 0)) -> 40 | C25: =IF(C23/16>1, IF((SUM(C24, C26:C34) + VLOOKUP($B$46, 'DB CONECTOR'!$K$1:$L$2, 2, FALSE)*2)/C23 <= $B$44, VLOOKUP($B$46, 'DB CONECTOR'!$K$1:$L$2, 2, FALSE)*2, 0), IF((SUM(C24, C26:C34) + VLOOKUP($B$46, 'DB CONECTOR'!$K$1:$L$2, 2, FALSE))/C23 <= $B$44, VLOOKUP($B$46, 'DB CONECTOR'!$K$1:$L$2, 2, FALSE), 0)) -> 40 | D25: =IF(D23/16>1, IF((SUM(D24, D26:D34) + VLOOKUP($B$46, 'DB CONECTOR'!$K$1:$L$2, 2, FALSE)*2)/D23 <= $B$44, VLOOKUP($B$46, 'DB CONECTOR'!$K$1:$L$2, 2, FALSE)*2, 0), IF((SUM(D24, D26:D34) + VLOOKUP($B$46, 'DB CONECTOR'!$K$1:$L$2, 2, FALSE))/D23 <= $B$44, VLOOKUP($B$46, 'DB CONECTOR'!$K$1:$L$2, 2, FALSE), 0)) -> 40 | E25: =IF(E23/16>1, IF((SUM(E24, E26:E34) + VLOOKUP($B$46, 'DB CONECTOR'!$K$1:$L$2, 2, FALSE)*2)/E23 <= $B$44, VLOOKUP($B$46, 'DB CONECTOR'!$K$1:$L$2, 2, FALSE)*2, 0), IF((SUM(E24, E26:E34) + VLOOKUP($B$46, 'DB CONECTOR'!$K$1:$L$2, 2, FALSE))/E23 <= $B$44, VLOOKUP($B$46, 'DB CONECTOR'!$K$1:$L$2, 2, FALSE), 0)) -> 40 | F25: =IF(F23/16>1, IF((SUM(F24, F26:F34) + VLOOKUP($B$46, 'DB CONECTOR'!$K$1:$L$2, 2, FALSE)*2)/F23 <= $B$44, VLOOKUP($B$46, 'DB CONECTOR'!$K$1:$L$2, 2, FALSE)*2, 0), IF((SUM(F24, F26:F34) + VLOOKUP($B$46, 'DB CONECTOR'!$K$1:$L$2, 2, FALSE))/F23 <= $B$44, VLOOKUP($B$46, 'DB CONECTOR'!$K$1:$L$2, 2, FALSE), 0)) -> 40 | G25: =IF(G23/16>1, IF((SUM(G24, G26:G34) + VLOOKUP($B$46, 'DB CONECTOR'!$K$1:$L$2, 2, FALSE)*2)/G23 <= $B$44, VLOOKUP($B$46, 'DB CONECTOR'!$K$1:$L$2, 2, FALSE)*2, 0), IF((SUM(G24, G26:G34) + VLOOKUP($B$46, 'DB CONECTOR'!$K$1:$L$2, 2, FALSE))/G23 <= $B$44, VLOOKUP($B$46, 'DB CONECTOR'!$K$1:$L$2, 2, FALSE), 0)) -> 40 | H25: =IF(H23/16>1, IF((SUM(H24, H26:H34) + VLOOKUP($B$46, 'DB CONECTOR'!$K$1:$L$2, 2, FALSE)*2)/H23 <= $B$44, VLOOKUP($B$46, 'DB CONECTOR'!$K$1:$L$2, 2, FALSE)*2, 0), IF((SUM(H24, H26:H34) + VLOOKUP($B$46, 'DB CONECTOR'!$K$1:$L$2, 2, FALSE))/H23 <= $B$44, VLOOKUP($B$46, 'DB CONECTOR'!$K$1:$L$2, 2, FALSE), 0)) -> 40 | I25: =IF(I23/16>1, IF((SUM(I24, I26:I34) + VLOOKUP($B$46, 'DB CONECTOR'!$K$1:$L$2, 2, FALSE)*2)/I23 <= $B$44, VLOOKUP($B$46, 'DB CONECTOR'!$K$1:$L$2, 2, FALSE)*2, 0), IF((SUM(I24, I26:I34) + VLOOKUP($B$46, 'DB CONECTOR'!$K$1:$L$2, 2, FALSE))/I23 <= $B$44, VLOOKUP($B$46, 'DB CONECTOR'!$K$1:$L$2, 2, FALSE), 0)) -> 80 | J25: =IF(J23/16>1, IF((SUM(J24, J26:J34) + VLOOKUP($B$46, 'DB CONECTOR'!$K$1:$L$2, 2, FALSE)*2)/J23 <= $B$44, VLOOKUP($B$46, 'DB CONECTOR'!$K$1:$L$2, 2, FALSE)*2, 0), IF((SUM(J24, J26:J34) + VLOOKUP($B$46, 'DB CONECTOR'!$K$1:$L$2, 2, FALSE))/J23 <= $B$44, VLOOKUP($B$46, 'DB CONECTOR'!$K$1:$L$2, 2, FALSE), 0)) -> 80 | K25: =K7 -> Tipo: Naturalista acreditado
A26: Ingreso a Destinos | B26: =$B$8*B23 -> 80 | C26: =$B$8*C23 -> 88 | D26: =$B$8*D23 -> 96 | E26: =$B$8*E23 -> 104 | F26: =$B$8*F23 -> 112 | G26: =$B$8*G23 -> 120 | H26: =$B$8*H23 -> 128 | I26: =$B$8*I23 -> 192 | J26: =$B$8*J23 -> 352 | K26: =K8 -> Entradas a reserva / atractivo
A27: Actividades | B27: =$B$9*B23 -> 0 | C27: =$B$9*C23 -> 0 | D27: =$B$9*D23 -> 0 | E27: =$B$9*E23 -> 0 | F27: =$B$8*F23 -> 112 | G27: =$B$14*G23 -> 0 | H27: =$B$14*H23 -> 0 | I27: =$B$14*I23 -> 0 | J27: =$B$14*J23 -> 0 | K27: =K9 -> Juegos, Recreaciones, Etc
A28: Kit de Primeros Auxilio | B28: =$B$10*B23 -> 0 | C28: =$B$10*C23 -> 0 | D28: =$B$10*D23 -> 0 | E28: =$B$10*E23 -> 0 | F28: =$B$9*F23 -> 0 | G28: =$B$15*G23 -> 0 | H28: =$B$15*H23 -> 0 | I28: =$B$15*I23 -> 0 | J28: =$B$15*J23 -> 0 | K28: =K10 -> Pastillas para el mareo, estomago y demas
A29: Kit de Dulces | B29: =$B$11*B23 -> 0 | C29: =$B$11*C23 -> 0 | D29: =$B$11*D23 -> 0 | E29: =$B$11*E23 -> 0 | F29: =$B$10*F23 -> 0 | G29: =$B$16*G23 -> 0 | H29: =$B$16*H23 -> 0 | I29: =$B$16*I23 -> 0 | J29: =$B$16*J23 -> 0 | K29: =K11 -> Kit de Dulces
A30: Hidratacion | B30: =$B$12*B23 -> 0 | C30: =$B$12*C23 -> 0 | D30: =$B$12*D23 -> 0 | E30: =$B$12*E23 -> 0 | F30: =$B$12*F23 -> 0 | G30: =$B$12*G23 -> 0 | H30: =$B$12*H23 -> 0 | I30: =$B$12*I23 -> 0 | J30: =$B$12*J23 -> 0 | K30: =K12 -> Botella de Agua
A31: Alimentacion | B31: =$B$13*B23 -> 0 | C31: =$B$13*C23 -> 0 | D31: =$B$13*D23 -> 0 | E31: =$B$13*E23 -> 0 | F31: =$B$13*F23 -> 0 | G31: =$B$13*G23 -> 0 | H31: =$B$13*H23 -> 0 | I31: =$B$13*I23 -> 0 | J31: =$B$13*J23 -> 0 | K31: =K13 -> Alimentacion si esta incluida
A32: Seguro de viaje | B32: =$B$14*B23 -> 0 | C32: =$B$14*C23 -> 0 | D32: =$B$14*D23 -> 0 | E32: =$B$14*E23 -> 0 | F32: =$B$14*F23 -> 0 | G32: =$B$14*G23 -> 0 | H32: =$B$14*H23 -> 0 | I32: =$B$14*I23 -> 0 | J32: =$B$14*J23 -> 0 | K32: =K14 -> Valor del seguro
A33: Patente de Tour | B33: =$B$15*B23 -> 0 | C33: =$B$15*C23 -> 0 | D33: =$B$15*D23 -> 0 | E33: =$B$15*E23 -> 0 | F33: =$B$15*F23 -> 0 | G33: =$B$15*G23 -> 0 | H33: =$B$15*H23 -> 0 | I33: =$B$15*I23 -> 0 | J33: =$B$15*J23 -> 0 | K33: =K15 -> Costo de la patente por pax
A34: Otros Costos | B34: =$B$16*B23 -> 0 | C34: =$B$16*C23 -> 0 | D34: =$B$16*D23 -> 0 | E34: =$B$16*E23 -> 0 | F34: =$B$16*F23 -> 0 | G34: =$B$16*G23 -> 0 | H34: =$B$16*H23 -> 0 | I34: =$B$16*I23 -> 0 | J34: =$B$16*J23 -> 0 | K34: =K16 -> Admin 15%, Marketing 10%, Tech 5%
A35: TOTAL COSTO (2-4 pax) | B35: =SUM(B24:B34) -> 240 | C35: =SUM(C24:C34) -> 278 | D35: =SUM(D24:D34) -> 286 | E35: =SUM(E24:E34) -> 324 | F35: =SUM(F24:F34) -> 444 | G35: =SUM(G24:G34) -> 340 | H35: =SUM(H24:H34) -> 348 | I35: =SUM(I24:I34) -> 272 | J35: =SUM(J24:J34) -> 432 | K35: Costo operativo total base
A36: COSTO UNITARIO | B36: =B35/B23 -> 24 | C36: =C35/C23 -> 25.272727 | D36: =D35/D23 -> 23.833333 | E36: =E35/E23 -> 24.923077 | F36: =F35/F23 -> 31.714286 | G36: =G35/G23 -> 22.666667 | H36: =H35/H23 -> 21.75 | I36: =I35/I23 -> 11.333333 | J36: =J35/J23 -> 9.8181818 | K36: Costo operativo por persona
A37: =CONCATENATE("UTILIDAD ",TEXT($B$43,"0%")) -> UTILIDAD 30% | B37: =IF(B36<=$B$44,$B$44,IF(MROUND(B36 * (1 + $B$43), 5) > $B$44, 0, $B$44)) -> 35 | C37: =IF(C36<=$B$44,$B$44,IF(MROUND(C36 * (1 + $B$43), 5) > $B$44, 0, $B$44)) -> 35 | D37: =IF(D36<=$B$44,$B$44,IF(MROUND(D36 * (1 + $B$43), 5) > $B$44, 0, $B$44)) -> 35 | E37: =IF(E36<=$B$44,$B$44,IF(MROUND(E36 * (1 + $B$43), 5) > $B$44, 0, $B$44)) -> 35 | F37: =IF(F36<=$B$44,$B$44,IF(MROUND(F36 * (1 + $B$43), 5) > $B$44, 0, $B$44)) -> 35 | G37: =IF(G36<=$B$44,$B$44,IF(MROUND(G36 * (1 + $B$43), 5) > $B$44, 0, $B$44)) -> 35 | H37: =IF(H36<=$B$44,$B$44,IF(MROUND(H36 * (1 + $B$43), 5) > $B$44, 0, $B$44)) -> 35 | I37: =IF(I36<=$B$44,$B$44,IF(MROUND(I36 * (1 + $B$43), 5) > $B$44, 0, $B$44)) -> 35 | J37: =IF(J36<=$B$44,$B$44,IF(MROUND(J36 * (1 + $B$43), 5) > $B$44, 0, $B$44)) -> 35 | K37: =CONCATENATE("Aumentar ",TEXT($B$43,"0%")," de ganancia") -> Aumentar 30% de ganancia
A38: UTILIDAD ALCANZADA | B38: =IF(B37<=$B$44,IFERROR((B37 - B36) / B36, 0),0) -> 0.45833333 | C38: =IF(C37<=$B$43,IFERROR((C37 - C36) / C36, 0),0) -> 0 | D38: =IF(D37<=$B$43,IFERROR((D37 - D36) / D36, 0),0) -> 0 | E38: =IF(E37<=$B$43,IFERROR((E37 - E36) / E36, 0),0) -> 0 | F38: =IF(F37<=$B$43,IFERROR((F37 - F36) / F36, 0),0) -> 0 | G38: =IF(G37<=$B$43,IFERROR((G37 - G36) / G36, 0),0) -> 0 | H38: =IF(H37<=$B$43,IFERROR((H37 - H36) / H36, 0),0) -> 0 | I38: =IF(I37<=$B$43,IFERROR((I37 - I36) / I36, 0),0) -> 0 | J38: =IF(J37<=$B$43,IFERROR((J37 - J36) / J36, 0),0) -> 0 | K38: Valor Real Alcanzado
A42: DATOS BASE DE TOUR
A43: UTILIDAD ESTIMADA | B43: 0.3
A44: VALOR BASE | B44: 35
A45: PROVEEDOR DE TRANSPORTE | B45: TRANSTOUR CIUDAD ROJA
...

Sheet VIABILIDAD FINANCIERA
A1: 6.2 MATRIZ DE SENSIBILIDAD DE MARGEN
A2: Tarifa Venta PAX / PVP : | B2: 3 | C2: ='MODELOS DE COSTOS'!B44 -> 35
A3: Ocupación | B3: Costo / Pax ($) | C3: Margen Bruto ($) | D3: % Margen | F3: =IFERROR(__xludf.DUMMYFUNCTION("FILTER(A3:D21,D3:D21 >0)"),"Ocupación") -> Ocupación | G3: =IFERROR(__xludf.DUMMYFUNCTION("""COMPUTED_VALUE"""),"Costo / Pax ($)") -> Costo / Pax ($) | H3: =IFERROR(__xludf.DUMMYFUNCTION("""COMPUTED_VALUE"""),"Margen Bruto ($)") -> Margen Bruto ($) | I3: =IFERROR(__xludf.DUMMYFUNCTION("""COMPUTED_VALUE"""),"% Margen") -> % Margen
A4: 1 | B4: ='MODELOS DE COSTOS'!B18 -> 88 | C4: =IF(OR(B4<=0,B4="",$C$2=0.01),0,$C$2-B4) -> -53 | D4: =IFERROR(C4/$C$2,0) -> -1.5142857 | F4: =IFERROR(__xludf.DUMMYFUNCTION("""COMPUTED_VALUE"""),3.0) -> 3 | G4: =IFERROR(__xludf.DUMMYFUNCTION("""COMPUTED_VALUE"""),34.666666666666664) -> 34.666667 | H4: =IFERROR(__xludf.DUMMYFUNCTION("""COMPUTED_VALUE"""),0.3333333333333357) -> 0.33333333 | I4: =IFERROR(__xludf.DUMMYFUNCTION("""COMPUTED_VALUE"""),0.009523809523809592) -> 0.0095238095
A5: 2 | B5: ='MODELOS DE COSTOS'!C18 -> 48 | C5: =IF(OR(B5<=0,B5="",$C$2=0.01),0,$C$2-B5) -> -13 | D5: =IFERROR(C5/$C$2,0) -> -0.37142857 | F5: =IFERROR(__xludf.DUMMYFUNCTION("""COMPUTED_VALUE"""),4.0) -> 4 | G5: =IFERROR(__xludf.DUMMYFUNCTION("""COMPUTED_VALUE"""),28.0) -> 28 | H5: =IFERROR(__xludf.DUMMYFUNCTION("""COMPUTED_VALUE"""),7.0) -> 7 | I5: =IFERROR(__xludf.DUMMYFUNCTION("""COMPUTED_VALUE"""),0.2) -> 0.2
A6: 3 | B6: ='MODELOS DE COSTOS'!D18 -> 34.666667 | C6: =IF(OR(B6<=0,B6="",$C$2=0.01),0,$C$2-B6) -> 0.33333333 | D6: =IFERROR(C6/$C$2,0) -> 0.0095238095 | F6: =IFERROR(__xludf.DUMMYFUNCTION("""COMPUTED_VALUE"""),5.0) -> 5 | G6: =IFERROR(__xludf.DUMMYFUNCTION("""COMPUTED_VALUE"""),34.0) -> 34 | H6: =IFERROR(__xludf.DUMMYFUNCTION("""COMPUTED_VALUE"""),1.0) -> 1 | I6: =IFERROR(__xludf.DUMMYFUNCTION("""COMPUTED_VALUE"""),0.02857142857142857) -> 0.028571429
A7: 4 | B7: ='MODELOS DE COSTOS'!E18 -> 28 | C7: =IF(OR(B7<=0,B7="",$C$2=0.01),0,$C$2-B7) -> 7 | D7: =IFERROR(C7/$C$2,0) -> 0.2 | F7: =IFERROR(__xludf.DUMMYFUNCTION("""COMPUTED_VALUE"""),6.0) -> 6 | G7: =IFERROR(__xludf.DUMMYFUNCTION("""COMPUTED_VALUE"""),29.666666666666668) -> 29.666667 | H7: =IFERROR(__xludf.DUMMYFUNCTION("""COMPUTED_VALUE"""),5.333333333333332) -> 5.3333333 | I7: =IFERROR(__xludf.DUMMYFUNCTION("""COMPUTED_VALUE"""),0.15238095238095234) -> 0.15238095
A8: 5 | B8: ='MODELOS DE COSTOS'!F18 -> 34 | C8: =IF(OR(B8<=0,B8="",$C$2=0.01),0,$C$2-B8) -> 1 | D8: =IFERROR(C8/$C$2,0) -> 0.028571429 | F8: =IFERROR(__xludf.DUMMYFUNCTION("""COMPUTED_VALUE"""),7.0) -> 7 | G8: =IFERROR(__xludf.DUMMYFUNCTION("""COMPUTED_VALUE"""),26.571428571428573) -> 26.571429 | H8: =IFERROR(__xludf.DUMMYFUNCTION("""COMPUTED_VALUE"""),8.428571428571427) -> 8.4285714 | I8: =IFERROR(__xludf.DUMMYFUNCTION("""COMPUTED_VALUE"""),0.2408163265306122) -> 0.24081633
A9: 6 | B9: ='MODELOS DE COSTOS'!G18 -> 29.666667 | C9: =IF(OR(B9<=0,B9="",$C$2=0.01),0,$C$2-B9) -> 5.3333333 | D9: =IFERROR(C9/$C$2,0) -> 0.15238095 | F9: =IFERROR(__xludf.DUMMYFUNCTION("""COMPUTED_VALUE"""),8.0) -> 8 | G9: =IFERROR(__xludf.DUMMYFUNCTION("""COMPUTED_VALUE"""),28.0) -> 28 | H9: =IFERROR(__xludf.DUMMYFUNCTION("""COMPUTED_VALUE"""),7.0) -> 7 | I9: =IFERROR(__xludf.DUMMYFUNCTION("""COMPUTED_VALUE"""),0.2) -> 0.2
A10: 7 | B10: ='MODELOS DE COSTOS'!H18 -> 26.571429 | C10: =IF(OR(B10<=0,B10="",$C$2=0.01),0,$C$2-B10) -> 8.4285714 | D10: =IFERROR(C10/$C$2,0) -> 0.24081633 | F10: =IFERROR(__xludf.DUMMYFUNCTION("""COMPUTED_VALUE"""),9.0) -> 9 | G10: =IFERROR(__xludf.DUMMYFUNCTION("""COMPUTED_VALUE"""),25.77777777777778) -> 25.777778 | H10: =IFERROR(__xludf.DUMMYFUNCTION("""COMPUTED_VALUE"""),9.222222222222221) -> 9.2222222 | I10: =IFERROR(__xludf.DUMMYFUNCTION("""COMPUTED_VALUE"""),0.26349206349206344) -> 0.26349206
A11: 8 | B11: ='MODELOS DE COSTOS'!I18 -> 28 | C11: =IF(OR(B11<=0,B11="",$C$2=0.01),0,$C$2-B11) -> 7 | D11: =IFERROR(C11/$C$2,0) -> 0.2 | F11: =IFERROR(__xludf.DUMMYFUNCTION("""COMPUTED_VALUE"""),10.0) -> 10 | G11: =IFERROR(__xludf.DUMMYFUNCTION("""COMPUTED_VALUE"""),24.0) -> 24 | H11: =IFERROR(__xludf.DUMMYFUNCTION("""COMPUTED_VALUE"""),11.0) -> 11 | I11: =IFERROR(__xludf.DUMMYFUNCTION("""COMPUTED_VALUE"""),0.3142857142857143) -> 0.31428571
A12: 9 | B12: ='MODELOS DE COSTOS'!J18 -> 25.777778 | C12: =IF(OR(B12<=0,B12="",$C$2=0.01),0,$C$2-B12) -> 9.2222222 | D12: =IFERROR(C12/$C$2,0) -> 0.26349206 | F12: =IFERROR(__xludf.DUMMYFUNCTION("""COMPUTED_VALUE"""),11.0) -> 11 | G12: =IFERROR(__xludf.DUMMYFUNCTION("""COMPUTED_VALUE"""),25.272727272727273) -> 25.272727 | H12: =IFERROR(__xludf.DUMMYFUNCTION("""COMPUTED_VALUE"""),9.727272727272727) -> 9.7272727 | I12: =IFERROR(__xludf.DUMMYFUNCTION("""COMPUTED_VALUE"""),0.2779220779220779) -> 0.27792208
A13: 10 | B13: ='MODELOS DE COSTOS'!B36 -> 24 | C13: =IF(OR(B13<=0,B13="",$C$2=0.01),0,$C$2-B13) -> 11 | D13: =IFERROR(C13/$C$2,0) -> 0.31428571 | F13: =IFERROR(__xludf.DUMMYFUNCTION("""COMPUTED_VALUE"""),12.0) -> 12 | G13: =IFERROR(__xludf.DUMMYFUNCTION("""COMPUTED_VALUE"""),23.833333333333332) -> 23.833333 | H13: =IFERROR(__xludf.DUMMYFUNCTION("""COMPUTED_VALUE"""),11.166666666666668) -> 11.166667 | I13: =IFERROR(__xludf.DUMMYFUNCTION("""COMPUTED_VALUE"""),0.3190476190476191) -> 0.31904762
A14: 11 | B14: ='MODELOS DE COSTOS'!C36 -> 25.272727 | C14: =IF(OR(B14<=0,B14="",$C$2=0.01),0,$C$2-B14) -> 9.7272727 | D14: =IFERROR(C14/$C$2,0) -> 0.27792208 | F14: =IFERROR(__xludf.DUMMYFUNCTION("""COMPUTED_VALUE"""),13.0) -> 13 | G14: =IFERROR(__xludf.DUMMYFUNCTION("""COMPUTED_VALUE"""),24.923076923076923) -> 24.923077 | H14: =IFERROR(__xludf.DUMMYFUNCTION("""COMPUTED_VALUE"""),10.076923076923077) -> 10.076923 | I14: =IFERROR(__xludf.DUMMYFUNCTION("""COMPUTED_VALUE"""),0.2879120879120879) -> 0.28791209
A15: 12 | B15: ='MODELOS DE COSTOS'!D36 -> 23.833333 | C15: =IF(OR(B15<=0,B15="",$C$2=0.01),0,$C$2-B15) -> 11.166667 | D15: =IFERROR(C15/$C$2,0) -> 0.31904762 | F15: =IFERROR(__xludf.DUMMYFUNCTION("""COMPUTED_VALUE"""),14.0) -> 14 | G15: =IFERROR(__xludf.DUMMYFUNCTION("""COMPUTED_VALUE"""),31.714285714285715) -> 31.714286 | H15: =IFERROR(__xludf.DUMMYFUNCTION("""COMPUTED_VALUE"""),3.2857142857142847) -> 3.2857143 | I15: =IFERROR(__xludf.DUMMYFUNCTION("""COMPUTED_VALUE"""),0.09387755102040814) -> 0.093877551
A16: 13 | B16: ='MODELOS DE COSTOS'!E36 -> 24.923077 | C16: =IF(OR(B16<=0,B16="",$C$2=0.01),0,$C$2-B16) -> 10.076923 | D16: =IFERROR(C16/$C$2,0) -> 0.28791209 | F16: =IFERROR(__xludf.DUMMYFUNCTION("""COMPUTED_VALUE"""),15.0) -> 15 | G16: =IFERROR(__xludf.DUMMYFUNCTION("""COMPUTED_VALUE"""),22.666666666666668) -> 22.666667 | H16: =IFERROR(__xludf.DUMMYFUNCTION("""COMPUTED_VALUE"""),12.333333333333332) -> 12.333333 | I16: =IFERROR(__xludf.DUMMYFUNCTION("""COMPUTED_VALUE"""),0.35238095238095235) -> 0.35238095
A17: 14 | B17: ='MODELOS DE COSTOS'!F36 -> 31.714286 | C17: =IF(OR(B17<=0,B17="",$C$2=0.01),0,$C$2-B17) -> 3.2857143 | D17: =IFERROR(C17/$C$2,0) -> 0.093877551 | F17: =IFERROR(__xludf.DUMMYFUNCTION("""COMPUTED_VALUE"""),16.0) -> 16 | G17: =IFERROR(__xludf.DUMMYFUNCTION("""COMPUTED_VALUE"""),21.75) -> 21.75 | H17: =IFERROR(__xludf.DUMMYFUNCTION("""COMPUTED_VALUE"""),13.25) -> 13.25 | I17: =IFERROR(__xludf.DUMMYFUNCTION("""COMPUTED_VALUE"""),0.37857142857142856) -> 0.37857143
A18: 15 | B18: ='MODELOS DE COSTOS'!G36 -> 22.666667 | C18: =IF(OR(B18<=0,B18="",$C$2=0.01),0,$C$2-B18) -> 12.333333 | D18: =IFERROR(C18/$C$2,0) -> 0.35238095 | F18: =IFERROR(__xludf.DUMMYFUNCTION("""COMPUTED_VALUE"""),24.0) -> 24 | G18: =IFERROR(__xludf.DUMMYFUNCTION("""COMPUTED_VALUE"""),11.333333333333334) -> 11.333333 | H18: =IFERROR(__xludf.DUMMYFUNCTION("""COMPUTED_VALUE"""),23.666666666666664) -> 23.666667 | I18: =IFERROR(__xludf.DUMMYFUNCTION("""COMPUTED_VALUE"""),0.6761904761904761) -> 0.67619048
A19: 16 | B19: ='MODELOS DE COSTOS'!H36 -> 21.75 | C19: =IF(OR(B19<=0,B19="",$C$2=0.01),0,$C$2-B19) -> 13.25 | D19: =IFERROR(C19/$C$2,0) -> 0.37857143 | F19: =IFERROR(__xludf.DUMMYFUNCTION("""COMPUTED_VALUE"""),44.0) -> 44 | G19: =IFERROR(__xludf.DUMMYFUNCTION("""COMPUTED_VALUE"""),9.818181818181818) -> 9.8181818 | H19: =IFERROR(__xludf.DUMMYFUNCTION("""COMPUTED_VALUE"""),25.18181818181818) -> 25.181818 | I19: =IFERROR(__xludf.DUMMYFUNCTION("""COMPUTED_VALUE"""),0.7194805194805194) -> 0.71948052
A20: 24 | B20: ='MODELOS DE COSTOS'!I36 -> 11.333333 | C20: =IF(OR(B20<=0,B20="",$C$2=0.01),0,$C$2-B20) -> 23.666667 | D20: =IFERROR(C20/$C$2,0) -> 0.67619048
A21: 44 | B21: ='MODELOS DE COSTOS'!J36 -> 9.8181818 | C21: =IF(OR(B21<=0,B21="",$C$2=0.01),0,$C$2-B21) -> 25.181818 | D21: =IFERROR(C21/$C$2,0) -> 0.71948052
A22: CALCULOS | B22: {=IFERROR(CONCATENATE("RENTA: ", INDEX($A$4:$A$21, MATCH(TRUE, $B$4:$B$21 < $C$2, 0)), " PAX", CHAR(10), "COSTO: ", INDEX($B$4:$B$21, MATCH(TRUE, $B$4:$B$21 < $C$2, 0))), "NO ENCONTRADO")} -> RENTA: 3 PAX COSTO: 34,6666666666667 | C22: =IFERROR(__xludf.DUMMYFUNCTION("IFERROR(CONCATENATE( ""MIN: "", TEXT(MIN(FILTER($C$4:$C$21, $C$4:$C$21 > 0)), ""$#,##0.00""), CHAR(10), ""MEDIA: "", TEXT(MEDIAN(FILTER($C$4:$C$21, $C$4:$C$21 > 0)), ""$#,##0.00""), CHAR(10), ""MODA: "", IFERROR(TEXT(MODE(FILTER($C$4:$C$21, $C$4:$C$"&"21 > 0)), ""$#,##0.00""), ""N/D""), CHAR(10), ""PROD: "", TEXT(AVERAGE(FILTER($C$4:$C$21, $C$4:$C$21 > 0)), ""$#,##0.00""), CHAR(10), ""MAX: "", TEXT(MAX(FILTER($C$4:$C$21, $C$4:$C$21 > 0)), ""$#,##0.00"") ), 0)"),"MIN: $0,33 MEDIA: $9,47 MODA: $7,00 PROD: $9,88 MAX: $25,18") -> MIN: $0,33 MEDIA: $9,47 MODA: $7,00 PROD: $9,88 MAX: $25,18 | D22: =IFERROR(__xludf.DUMMYFUNCTION("IFERROR(CONCATENATE( ""MIN: "", TEXT(MIN(FILTER($D$4:$D$21, $D$4:$D$21 > 0)), ""0.0%""), CHAR(10), ""MEDIA: "", TEXT(MEDIAN(FILTER($D$4:$D$21, $D$4:$D$21 > 0)), ""0.0%""), CHAR(10), ""MODA: "", IFERROR(TEXT(MODE(FILTER($D$4:$D$21, $D$4:$D$21 > 0)), "&"""0.0%""), ""N/D""), CHAR(10), ""PROD: "", TEXT(AVERAGE(FILTER($D$4:$D$21, $D$4:$D$21 > 0)), ""0.0%""), CHAR(10), ""MAX: "", TEXT(MAX(FILTER($D$4:$D$21, $D$4:$D$21 > 0)), ""0.0%"") ), 0)"),"MIN: 1,0% MEDIA: 27,1% MODA: 20,0% PROD: 28,2% MAX: 71,9%") -> MIN: 1,0% MEDIA: 27,1% MODA: 20,0% PROD: 28,2% MAX: 71,9%
A25: 6.4 MATRIZ DE PRECIOS POR CANAL DE DISTRIBUCIÓN
A27: Canal de Venta | B27: Precio PVP ($) | C27: Comisión / Dto. | D27: Ingreso Neto ($)
A28: Público Directo (Web oficial) | B28: =$C$2 -> 35 | C28: 0 | D28: =B28*(1 + C28) -> 35
A29: WhatsApp / Pago anticipado (-5% dto) | B29: =$C$2 -> 35 | C29: -0.05 | D29: =B29*(1 + C29) -> 33.25
A30: Agencias Minoristas (15% com) | B30: =$C$2 -> 35 | C30: -0.15 | D30: =B30*(1 + C30) -> 29.75
A31: Mayoristas de Turismo (20% com) | B31: =$C$2 -> 35 | C31: -0.2 | D31: =B31*(1 + C31) -> 28
A32: OTAs (GetYourGuide / Viator 22%) | B32: =$C$2 -> 35 | C32: -0.22 | D32: =B32*(1 + C32) -> 27.3
A33: Maximo Descuento | B33: =$C$2 -> 35 | C33: -0.25 | D33: =B33*(1 + C33) -> 26.25
A34: Grupos (8+ pax) (-10% dto) | B34: =$C$2 -> 35 | C34: -0.1 | D34: =B34*(1 + C34) -> 31.5
A35: Privado Exclusivo (+60% tarifa) | B35: =$C$2 -> 35 | C35: 0.6 | D35: =B35*(1 + C35) -> 56
A36: Temporada Baja (-7,5% descuento) | B36: =$C$2 -> 35 | C36: -7.5% | D36: =B36*(1 + C36) -> 32.375
A37: Promedio General por Canal | D37: =AVERAGE(D28:D36) -> 33.269444
